
import { render } from '@testing-library/react';
import { describe, it, expect, vi } from 'vitest';
import { ErrorBoundary } from '@/components/common/ErrorBoundary';

const ThrowError = ({ shouldThrow }: { shouldThrow: boolean }) => {
  if (shouldThrow) {
    throw new Error('Test error');
  }
  return <div>No error</div>;
};

describe('ErrorBoundary', () => {
  it('renders children when there is no error', () => {
    const { getByText } = render(
      <ErrorBoundary>
        <ThrowError shouldThrow={false} />
      </ErrorBoundary>
    );

    expect(getByText('No error')).toBeDefined();
  });

  it('renders error UI when there is an error', () => {
    // Suppress console.error for this test
    const consoleSpy = vi.spyOn(console, 'error').mockImplementation(() => {});

    const { getByText } = render(
      <ErrorBoundary>
        <ThrowError shouldThrow={true} />
      </ErrorBoundary>
    );

    expect(getByText('Algo deu errado')).toBeDefined();
    expect(getByText('Tentar novamente')).toBeDefined();

    consoleSpy.mockRestore();
  });

  it('renders custom fallback when provided', () => {
    const consoleSpy = vi.spyOn(console, 'error').mockImplementation(() => {});
    const customFallback = <div>Custom error message</div>;

    const { getByText } = render(
      <ErrorBoundary fallback={customFallback}>
        <ThrowError shouldThrow={true} />
      </ErrorBoundary>
    );

    expect(getByText('Custom error message')).toBeDefined();

    consoleSpy.mockRestore();
  });

  it('calls onError callback when error occurs', () => {
    const consoleSpy = vi.spyOn(console, 'error').mockImplementation(() => {});
    const onError = vi.fn();

    render(
      <ErrorBoundary onError={onError}>
        <ThrowError shouldThrow={true} />
      </ErrorBoundary>
    );

    expect(onError).toHaveBeenCalledWith(
      expect.any(Error),
      expect.objectContaining({
        componentStack: expect.any(String)
      })
    );

    consoleSpy.mockRestore();
  });
});
